2019-02-02 23:33:06,754 ERROR: Exception on / [GET] [in /Users/burt/PycharmProjects/microblog/venv/lib/python3.6/site-packages/flask/app.py:1761]
Traceback (most recent call last):
  File "/Users/burt/PycharmProjects/microblog/venv/lib/python3.6/site-packages/flask/app.py", line 2292, in wsgi_app
    response = self.full_dispatch_request()
  File "/Users/burt/PycharmProjects/microblog/venv/lib/python3.6/site-packages/flask/app.py", line 1815, in full_dispatch_request
    rv = self.handle_user_exception(e)
  File "/Users/burt/PycharmProjects/microblog/venv/lib/python3.6/site-packages/flask/app.py", line 1718, in handle_user_exception
    reraise(exc_type, exc_value, tb)
  File "/Users/burt/PycharmProjects/microblog/venv/lib/python3.6/site-packages/flask/_compat.py", line 35, in reraise
    raise value
  File "/Users/burt/PycharmProjects/microblog/venv/lib/python3.6/site-packages/flask/app.py", line 1813, in full_dispatch_request
    rv = self.dispatch_request()
  File "/Users/burt/PycharmProjects/microblog/venv/lib/python3.6/site-packages/flask/app.py", line 1799, in dispatch_request
    return self.view_functions[rule.endpoint](**req.view_args)
  File "/Users/burt/PycharmProjects/microblog/venv/lib/python3.6/site-packages/flask_login/utils.py", line 260, in decorated_view
    return current_app.login_manager.unauthorized()
  File "/Users/burt/PycharmProjects/microblog/venv/lib/python3.6/site-packages/flask_login/login_manager.py", line 175, in unauthorized
    redirect_url = make_login_url(login_view, next_url=request.url)
  File "/Users/burt/PycharmProjects/microblog/venv/lib/python3.6/site-packages/flask_login/utils.py", line 112, in login_url
    base = expand_login_view(login_view)
  File "/Users/burt/PycharmProjects/microblog/venv/lib/python3.6/site-packages/flask_login/utils.py", line 89, in expand_login_view
    return url_for(login_view)
  File "/Users/burt/PycharmProjects/microblog/venv/lib/python3.6/site-packages/flask/helpers.py", line 356, in url_for
    return appctx.app.handle_url_build_error(error, endpoint, values)
  File "/Users/burt/PycharmProjects/microblog/venv/lib/python3.6/site-packages/flask/app.py", line 2061, in handle_url_build_error
    reraise(exc_type, exc_value, tb)
  File "/Users/burt/PycharmProjects/microblog/venv/lib/python3.6/site-packages/flask/_compat.py", line 35, in reraise
    raise value
  File "/Users/burt/PycharmProjects/microblog/venv/lib/python3.6/site-packages/flask/helpers.py", line 345, in url_for
    force_external=external)
  File "/Users/burt/PycharmProjects/microblog/venv/lib/python3.6/site-packages/werkzeug/routing.py", line 1776, in build
    raise BuildError(endpoint, values, method, self)
werkzeug.routing.BuildError: Could not build url for endpoint 'login'. Did you mean 'auth.login' instead?
2019-02-02 23:35:46,718 INFO: Microblog startup [in /Users/burt/PycharmProjects/microblog/app/__init__.py:97]
2019-02-02 23:35:48,394 ERROR: Exception on / [GET] [in /Users/burt/PycharmProjects/microblog/venv/lib/python3.6/site-packages/flask/app.py:1761]
Traceback (most recent call last):
  File "/Users/burt/PycharmProjects/microblog/venv/lib/python3.6/site-packages/flask/app.py", line 2292, in wsgi_app
    response = self.full_dispatch_request()
  File "/Users/burt/PycharmProjects/microblog/venv/lib/python3.6/site-packages/flask/app.py", line 1815, in full_dispatch_request
    rv = self.handle_user_exception(e)
  File "/Users/burt/PycharmProjects/microblog/venv/lib/python3.6/site-packages/flask/app.py", line 1718, in handle_user_exception
    reraise(exc_type, exc_value, tb)
  File "/Users/burt/PycharmProjects/microblog/venv/lib/python3.6/site-packages/flask/_compat.py", line 35, in reraise
    raise value
  File "/Users/burt/PycharmProjects/microblog/venv/lib/python3.6/site-packages/flask/app.py", line 1813, in full_dispatch_request
    rv = self.dispatch_request()
  File "/Users/burt/PycharmProjects/microblog/venv/lib/python3.6/site-packages/flask/app.py", line 1799, in dispatch_request
    return self.view_functions[rule.endpoint](**req.view_args)
  File "/Users/burt/PycharmProjects/microblog/venv/lib/python3.6/site-packages/flask_login/utils.py", line 260, in decorated_view
    return current_app.login_manager.unauthorized()
  File "/Users/burt/PycharmProjects/microblog/venv/lib/python3.6/site-packages/flask_login/login_manager.py", line 175, in unauthorized
    redirect_url = make_login_url(login_view, next_url=request.url)
  File "/Users/burt/PycharmProjects/microblog/venv/lib/python3.6/site-packages/flask_login/utils.py", line 112, in login_url
    base = expand_login_view(login_view)
  File "/Users/burt/PycharmProjects/microblog/venv/lib/python3.6/site-packages/flask_login/utils.py", line 89, in expand_login_view
    return url_for(login_view)
  File "/Users/burt/PycharmProjects/microblog/venv/lib/python3.6/site-packages/flask/helpers.py", line 356, in url_for
    return appctx.app.handle_url_build_error(error, endpoint, values)
  File "/Users/burt/PycharmProjects/microblog/venv/lib/python3.6/site-packages/flask/app.py", line 2061, in handle_url_build_error
    reraise(exc_type, exc_value, tb)
  File "/Users/burt/PycharmProjects/microblog/venv/lib/python3.6/site-packages/flask/_compat.py", line 35, in reraise
    raise value
  File "/Users/burt/PycharmProjects/microblog/venv/lib/python3.6/site-packages/flask/helpers.py", line 345, in url_for
    force_external=external)
  File "/Users/burt/PycharmProjects/microblog/venv/lib/python3.6/site-packages/werkzeug/routing.py", line 1776, in build
    raise BuildError(endpoint, values, method, self)
werkzeug.routing.BuildError: Could not build url for endpoint 'login'. Did you mean 'auth.login' instead?
2019-02-02 23:38:53,215 INFO: Microblog startup [in /Users/burt/PycharmProjects/microblog/app/__init__.py:97]
2019-02-02 23:38:54,913 ERROR: Exception on /auth/login [GET] [in /Users/burt/PycharmProjects/microblog/venv/lib/python3.6/site-packages/flask/app.py:1761]
Traceback (most recent call last):
  File "/Users/burt/PycharmProjects/microblog/venv/lib/python3.6/site-packages/flask/app.py", line 2292, in wsgi_app
    response = self.full_dispatch_request()
  File "/Users/burt/PycharmProjects/microblog/venv/lib/python3.6/site-packages/flask/app.py", line 1815, in full_dispatch_request
    rv = self.handle_user_exception(e)
  File "/Users/burt/PycharmProjects/microblog/venv/lib/python3.6/site-packages/flask/app.py", line 1718, in handle_user_exception
    reraise(exc_type, exc_value, tb)
  File "/Users/burt/PycharmProjects/microblog/venv/lib/python3.6/site-packages/flask/_compat.py", line 35, in reraise
    raise value
  File "/Users/burt/PycharmProjects/microblog/venv/lib/python3.6/site-packages/flask/app.py", line 1813, in full_dispatch_request
    rv = self.dispatch_request()
  File "/Users/burt/PycharmProjects/microblog/venv/lib/python3.6/site-packages/flask/app.py", line 1799, in dispatch_request
    return self.view_functions[rule.endpoint](**req.view_args)
  File "/Users/burt/PycharmProjects/microblog/app/auth/routes.py", line 47, in login
    return render_template('login.html', title='Sign In', form=form)
  File "/Users/burt/PycharmProjects/microblog/venv/lib/python3.6/site-packages/flask/templating.py", line 134, in render_template
    return _render(ctx.app.jinja_env.get_or_select_template(template_name_or_list),
  File "/Users/burt/PycharmProjects/microblog/venv/lib/python3.6/site-packages/jinja2/environment.py", line 869, in get_or_select_template
    return self.get_template(template_name_or_list, parent, globals)
  File "/Users/burt/PycharmProjects/microblog/venv/lib/python3.6/site-packages/jinja2/environment.py", line 830, in get_template
    return self._load_template(name, self.make_globals(globals))
  File "/Users/burt/PycharmProjects/microblog/venv/lib/python3.6/site-packages/jinja2/environment.py", line 804, in _load_template
    template = self.loader.load(self, name, globals)
  File "/Users/burt/PycharmProjects/microblog/venv/lib/python3.6/site-packages/jinja2/loaders.py", line 113, in load
    source, filename, uptodate = self.get_source(environment, name)
  File "/Users/burt/PycharmProjects/microblog/venv/lib/python3.6/site-packages/flask/templating.py", line 58, in get_source
    return self._get_source_fast(environment, template)
  File "/Users/burt/PycharmProjects/microblog/venv/lib/python3.6/site-packages/flask/templating.py", line 86, in _get_source_fast
    raise TemplateNotFound(template)
jinja2.exceptions.TemplateNotFound: login.html
2019-02-02 23:40:48,861 INFO: Microblog startup [in /Users/burt/PycharmProjects/microblog/app/__init__.py:97]
