2019-01-30 23:30:21,353 ERROR: Exception on /favicon.ico [GET] [in /Users/burt/PycharmProjects/microblog/venv/lib/python3.6/site-packages/flask/app.py:1761]
Traceback (most recent call last):
  File "/Users/burt/PycharmProjects/microblog/venv/lib/python3.6/site-packages/sqlalchemy/engine/base.py", line 724, in _commit_impl
    self.engine.dialect.do_commit(self.connection)
  File "/Users/burt/PycharmProjects/microblog/venv/lib/python3.6/site-packages/sqlalchemy/engine/default.py", line 462, in do_commit
    dbapi_connection.commit()
sqlite3.OperationalError: database is locked

The above exception was the direct cause of the following exception:

Traceback (most recent call last):
  File "/Users/burt/PycharmProjects/microblog/venv/lib/python3.6/site-packages/flask/app.py", line 2292, in wsgi_app
    response = self.full_dispatch_request()
  File "/Users/burt/PycharmProjects/microblog/venv/lib/python3.6/site-packages/flask/app.py", line 1815, in full_dispatch_request
    rv = self.handle_user_exception(e)
  File "/Users/burt/PycharmProjects/microblog/venv/lib/python3.6/site-packages/flask/app.py", line 1718, in handle_user_exception
    reraise(exc_type, exc_value, tb)
  File "/Users/burt/PycharmProjects/microblog/venv/lib/python3.6/site-packages/flask/_compat.py", line 35, in reraise
    raise value
  File "/Users/burt/PycharmProjects/microblog/venv/lib/python3.6/site-packages/flask/app.py", line 1811, in full_dispatch_request
    rv = self.preprocess_request()
  File "/Users/burt/PycharmProjects/microblog/venv/lib/python3.6/site-packages/flask/app.py", line 2087, in preprocess_request
    rv = func()
  File "/Users/burt/PycharmProjects/microblog/app/routes.py", line 30, in before_request
    db.session.commit()
  File "/Users/burt/PycharmProjects/microblog/venv/lib/python3.6/site-packages/sqlalchemy/orm/scoping.py", line 153, in do
    return getattr(self.registry(), name)(*args, **kwargs)
  File "/Users/burt/PycharmProjects/microblog/venv/lib/python3.6/site-packages/sqlalchemy/orm/session.py", line 954, in commit
    self.transaction.commit()
  File "/Users/burt/PycharmProjects/microblog/venv/lib/python3.6/site-packages/sqlalchemy/orm/session.py", line 471, in commit
    t[1].commit()
  File "/Users/burt/PycharmProjects/microblog/venv/lib/python3.6/site-packages/sqlalchemy/engine/base.py", line 1643, in commit
    self._do_commit()
  File "/Users/burt/PycharmProjects/microblog/venv/lib/python3.6/site-packages/sqlalchemy/engine/base.py", line 1674, in _do_commit
    self.connection._commit_impl()
  File "/Users/burt/PycharmProjects/microblog/venv/lib/python3.6/site-packages/sqlalchemy/engine/base.py", line 726, in _commit_impl
    self._handle_dbapi_exception(e, None, None, None, None)
  File "/Users/burt/PycharmProjects/microblog/venv/lib/python3.6/site-packages/sqlalchemy/engine/base.py", line 1413, in _handle_dbapi_exception
    exc_info
  File "/Users/burt/PycharmProjects/microblog/venv/lib/python3.6/site-packages/sqlalchemy/util/compat.py", line 265, in raise_from_cause
    reraise(type(exception), exception, tb=exc_tb, cause=cause)
  File "/Users/burt/PycharmProjects/microblog/venv/lib/python3.6/site-packages/sqlalchemy/util/compat.py", line 248, in reraise
    raise value.with_traceback(tb)
  File "/Users/burt/PycharmProjects/microblog/venv/lib/python3.6/site-packages/sqlalchemy/engine/base.py", line 724, in _commit_impl
    self.engine.dialect.do_commit(self.connection)
  File "/Users/burt/PycharmProjects/microblog/venv/lib/python3.6/site-packages/sqlalchemy/engine/default.py", line 462, in do_commit
    dbapi_connection.commit()
sqlalchemy.exc.OperationalError: (sqlite3.OperationalError) database is locked (Background on this error at: http://sqlalche.me/e/e3q8)
2019-01-30 23:33:50,291 ERROR: Exception on /index [GET] [in /Users/burt/PycharmProjects/microblog/venv/lib/python3.6/site-packages/flask/app.py:1761]
Traceback (most recent call last):
  File "/Users/burt/PycharmProjects/microblog/venv/lib/python3.6/site-packages/flask/app.py", line 2292, in wsgi_app
    response = self.full_dispatch_request()
  File "/Users/burt/PycharmProjects/microblog/venv/lib/python3.6/site-packages/flask/app.py", line 1815, in full_dispatch_request
    rv = self.handle_user_exception(e)
  File "/Users/burt/PycharmProjects/microblog/venv/lib/python3.6/site-packages/flask/app.py", line 1718, in handle_user_exception
    reraise(exc_type, exc_value, tb)
  File "/Users/burt/PycharmProjects/microblog/venv/lib/python3.6/site-packages/flask/_compat.py", line 35, in reraise
    raise value
  File "/Users/burt/PycharmProjects/microblog/venv/lib/python3.6/site-packages/flask/app.py", line 1813, in full_dispatch_request
    rv = self.dispatch_request()
  File "/Users/burt/PycharmProjects/microblog/venv/lib/python3.6/site-packages/flask/app.py", line 1799, in dispatch_request
    return self.view_functions[rule.endpoint](**req.view_args)
  File "/Users/burt/PycharmProjects/microblog/venv/lib/python3.6/site-packages/flask_login/utils.py", line 261, in decorated_view
    return func(*args, **kwargs)
  File "/Users/burt/PycharmProjects/microblog/app/routes.py", line 51, in index
    form=form, next_url=next_url, prev_url=prev_url)
  File "/Users/burt/PycharmProjects/microblog/venv/lib/python3.6/site-packages/flask/templating.py", line 135, in render_template
    context, ctx.app)
  File "/Users/burt/PycharmProjects/microblog/venv/lib/python3.6/site-packages/flask/templating.py", line 117, in _render
    rv = template.render(context)
  File "/Users/burt/PycharmProjects/microblog/venv/lib/python3.6/site-packages/jinja2/asyncsupport.py", line 76, in render
    return original_render(self, *args, **kwargs)
  File "/Users/burt/PycharmProjects/microblog/venv/lib/python3.6/site-packages/jinja2/environment.py", line 1008, in render
    return self.environment.handle_exception(exc_info, True)
  File "/Users/burt/PycharmProjects/microblog/venv/lib/python3.6/site-packages/jinja2/environment.py", line 780, in handle_exception
    reraise(exc_type, exc_value, tb)
  File "/Users/burt/PycharmProjects/microblog/venv/lib/python3.6/site-packages/jinja2/_compat.py", line 37, in reraise
    raise value.with_traceback(tb)
  File "/Users/burt/PycharmProjects/microblog/app/templates/index.html", line 2, in top-level template code
    {% import 'bootstrap/wtf.html' as wtf %}
  File "/Users/burt/PycharmProjects/microblog/app/templates/base.html", line 1, in top-level template code
    {% extends 'bootstrap/base.html' %}
  File "/Users/burt/PycharmProjects/microblog/venv/lib/python3.6/site-packages/flask_bootstrap/templates/bootstrap/base.html", line 1, in top-level template code
    {% block doc -%}
  File "/Users/burt/PycharmProjects/microblog/venv/lib/python3.6/site-packages/flask_bootstrap/templates/bootstrap/base.html", line 4, in block "doc"
    {%- block html %}
  File "/Users/burt/PycharmProjects/microblog/venv/lib/python3.6/site-packages/flask_bootstrap/templates/bootstrap/base.html", line 20, in block "html"
    {% block body -%}
  File "/Users/burt/PycharmProjects/microblog/venv/lib/python3.6/site-packages/flask_bootstrap/templates/bootstrap/base.html", line 23, in block "body"
    {% block content -%}
  File "/Users/burt/PycharmProjects/microblog/app/templates/base.html", line 51, in block "content"
    {% block app_content %}{% endblock %}
  File "/Users/burt/PycharmProjects/microblog/app/templates/index.html", line 17, in block "app_content"
    {% include "_post.html" %}
  File "/Users/burt/PycharmProjects/microblog/app/templates/_post.html", line 5, in top-level template code
    <img src="{{ post.author.avatar(70) }}" alt="">
jinja2.exceptions.UndefinedError: 'None' has no attribute 'avatar'
